Workbook

Sheet README
A1: RGC Neuroprotection Wheel: source data
A2: Graphical abstract of Malahov et al., “Pharmacological targeting of TNF-α, IL-1β and IL-6 signaling in retinal ganglion cell degeneration”.
A4: Sheets
A5: Experiments: one row per in vivo experiment (study × compound × model/species × route). Columns E, O and T are formulas.
A6: Drug classes: drug class → pathway branch (Figure 2 colours) and table of the manuscript. Used by column E of Experiments.
A7: References: the 68 references cited for these experiments, numbered as in the manuscript (DOI as given there).
A8: Summary: counts per drug class (the wheel sectors) and a check of every number quoted in the manuscript text.
A10: Which rows are drawn
A11: The wheel shows rows with In wheel = yes (In Tables 1–3 = yes and Include in figure = yes): 80 experiments.
A12: Two curated rows are kept for transparency but not drawn: Etanercept [56] sonication-induced traumatic optic neuropathy (not in Table 1) and BIRB 796 [88] squirrel monkey (non-rodent arm, not in Table 2).
A14: Definitions
A15: Treatment duration = days from first to last dose, inclusive (single dose = 1 d; continuous dosing = until sacrifice; 1 month = 30 d; several arms = longest).
... A23: Colour key: blue text = values taken from the manuscript text for checking; black = data or formulas.

Sheet Summary
A1: Check against the manuscript text
A2: Quantity | B2: From the data (formula) | C2: Manuscript text | D2: Match | E2: Note
A3: Experiments in Tables 1–3 (drawn in the wheel) | B3: =COUNTIFS(Experiments!$T$2:$T$83,"yes") -> 80 | C3: 80 | D3: =IF(ABS(B3-C3)<=0+0.000000001,"yes","CHECK") -> yes
A4: Compounds | B4: =SUMPRODUCT((Experiments!$T$2:$T$83="yes")/(COUNTIFS(Experiments!$C$2:$C$83,Experiments!$C$2:$C$83,Experiments!$T$2:$T$83,"yes")+(Experiments!$T$2:$T$83<>"yes"))) -> 49 | C4: 49 | D4: =IF(ABS(B4-C4)<=0+0.000000001,"yes","CHECK") -> yes
A5: Studies (distinct references) | B5: =SUMPRODUCT((Experiments!$T$2:$T$83="yes")/(COUNTIFS(Experiments!$G$2:$G$83,Experiments!$G$2:$G$83,Experiments!$T$2:$T$83,"yes")+(Experiments!$T$2:$T$83<>"yes"))) -> 68 | C5: 68 | D5: =IF(ABS(B5-C5)<=0+0.000000001,"yes","CHECK") -> yes
A6: Share using acute injury models | B6: =COUNTIFS(Experiments!$K$2:$K$83,"Acute injury",Experiments!$T$2:$T$83,"yes")/B3 -> 0.6375 | C6: 0.64 | D6: =IF(ABS(B6-C6)<=0.005+0.000000001,"yes","CHECK") -> yes
A7: Share using genetic or metabolic models | B7: =COUNTIFS(Experiments!$K$2:$K$83,"Genetic / metabolic",Experiments!$T$2:$T$83,"yes")/B3 -> 0.125 | C7: 0.12 | D7: =IF(ABS(B7-C7)<=0.005+0.000000001,"yes","CHECK") -> yes | E7: 10 of 80 = 12.5%. Standard rounding gives 13%; the text and Figure 3 say 12% (round-half-to-even). Consider writing 12.5%.
A8: Experiments with a single dose | B8: =COUNTIFS(Experiments!$O$2:$O$83,"Single dose",Experiments!$T$2:$T$83,"yes") -> 30 | C8: 30 | D8: =IF(ABS(B8-C8)<=0+0.000000001,"yes","CHECK") -> yes
A9: Repeated-dose regimens lasting 4 weeks or less | B9: =COUNTIFS(Experiments!$N$2:$N$83,">1",Experiments!$N$2:$N$83,"<=28",Experiments!$T$2:$T$83,"yes")/COUNTIFS(Experiments!$N$2:$N$83,">1",Experiments!$T$2:$T$83,"yes") -> 0.69387755 | C9: 0.69 | D9: =IF(ABS(B9-C9)<=0.005+0.000000001,"yes","CHECK") -> yes
A12: Experiments per drug class (wheel sectors, sorted by drug class)
A13: Drug class | B13: Pathway | C13: Experiments | D13: Systemic | E13: Intravitreal | F13: Topical | G13: Subconj. / retrobulbar | H13: Systemic + intravitreal | I13: Acute injury | J13: Induced OHT | K13: Genetic / metabolic | L13: Single dose | M13: Repeated dosing | N13: Duration not reported
A14: TNF-α | B14: =INDEX('Drug classes'!$B$2:$B$20,MATCH(A14,'Drug classes'!$A$2:$A$20,0)) -> TNF / RIPK / MAPK | C14: =COUNTIFS(Experiments!$D$2:$D$83,A14,Experiments!$T$2:$T$83,"yes") -> 11 | D14: =COUNTIFS(Experiments!$D$2:$D$83,$A14,Experiments!$L$2:$L$83,"Systemic",Experiments!$T$2:$T$83,"yes") -> 7 | E14: =COUNTIFS(Experiments!$D$2:$D$83,$A14,Experiments!$L$2:$L$83,"Intravitreal",Experiments!$T$2:$T$83,"yes") -> 2 | F14: =COUNTIFS(Experiments!$D$2:$D$83,$A14,Experiments!$L$2:$L$83,"Topical",Experiments!$T$2:$T$83,"yes") -> 0 | G14: =COUNTIFS(Experiments!$D$2:$D$83,$A14,Experiments!$L$2:$L$83,"Periocular",Experiments!$T$2:$T$83,"yes") -> 1 | H14: =COUNTIFS(Experiments!$D$2:$D$83,$A14,Experiments!$L$2:$L$83,"Combined",Experiments!$T$2:$T$83,"yes") -> 1 | I14: =COUNTIFS(Experiments!$D$2:$D$83,$A14,Experiments!$K$2:$K$83,"Acute injury",Experiments!$T$2:$T$83,"yes") -> 9 | J14: =COUNTIFS(Experiments!$D$2:$D$83,$A14,Experiments!$K$2:$K$83,"Induced OHT",Experiments!$T$2:$T$83,"yes") -> 2 | K14: =COUNTIFS(Experiments!$D$2:$D$83,$A14,Experiments!$K$2:$K$83,"Genetic / metabolic",Experiments!$T$2:$T$83,"yes") -> 0 | L14: =COUNTIFS(Experiments!$D$2:$D$83,$A14,Experiments!$O$2:$O$83,"Single dose",Experiments!$T$2:$T$83,"yes") -> 5 | M14: =COUNTIFS(Experiments!$D$2:$D$83,$A14,Experiments!$N$2:$N$83,">1",Experiments!$T$2:$T$83,"yes") -> 6 | N14: =COUNTIFS(Experiments!$D$2:$D$83,$A14,Experiments!$O$2:$O$83,"Not reported",Experiments!$T$2:$T$83,"yes") -> 0
A15: IL-1β | B15: =INDEX('Drug classes'!$B$2:$B$20,MATCH(A15,'Drug classes'!$A$2:$A$20,0)) -> TLR4 / IL-1R / NF-κB | C15: =COUNTIFS(Experiments!$D$2:$D$83,A15,Experiments!$T$2:$T$83,"yes") -> 2 | D15: =COUNTIFS(Experiments!$D$2:$D$83,$A15,Experiments!$L$2:$L$83,"Systemic",Experiments!$T$2:$T$83,"yes") -> 1 | E15: =COUNTIFS(Experiments!$D$2:$D$83,$A15,Experiments!$L$2:$L$83,"Intravitreal",Experiments!$T$2:$T$83,"yes") -> 1 | F15: =COUNTIFS(Experiments!$D$2:$D$83,$A15,Experiments!$L$2:$L$83,"Topical",Experiments!$T$2:$T$83,"yes") -> 0 | G15: =COUNTIFS(Experiments!$D$2:$D$83,$A15,Experiments!$L$2:$L$83,"Periocular",Experiments!$T$2:$T$83,"yes") -> 0 | H15: =COUNTIFS(Experiments!$D$2:$D$83,$A15,Experiments!$L$2:$L$83,"Combined",Experiments!$T$2:$T$83,"yes") -> 0 | I15: =COUNTIFS(Experiments!$D$2:$D$83,$A15,Experiments!$K$2:$K$83,"Acute injury",Experiments!$T$2:$T$83,"yes") -> 2 | J15: =COUNTIFS(Experiments!$D$2:$D$83,$A15,Experiments!$K$2:$K$83,"Induced OHT",Experiments!$T$2:$T$83,"yes") -> 0 | K15: =COUNTIFS(Experiments!$D$2:$D$83,$A15,Experiments!$K$2:$K$83,"Genetic / metabolic",Experiments!$T$2:$T$83,"yes") -> 0 | L15: =COUNTIFS(Experiments!$D$2:$D$83,$A15,Experiments!$O$2:$O$83,"Single dose",Experiments!$T$2:$T$83,"yes") -> 1 | M15: =COUNTIFS(Experiments!$D$2:$D$83,$A15,Experiments!$N$2:$N$83,">1",Experiments!$T$2:$T$83,"yes") -> 1 | N15: =COUNTIFS(Experiments!$D$2:$D$83,$A15,Experiments!$O$2:$O$83,"Not reported",Experiments!$T$2:$T$83,"yes") -> 0
A16: IL-6 | B16: =INDEX('Drug classes'!$B$2:$B$20,MATCH(A16,'Drug classes'!$A$2:$A$20,0)) -> IL-6 / JAK-STAT3 | C16: =COUNTIFS(Experiments!$D$2:$D$83,A16,Experiments!$T$2:$T$83,"yes") -> 1 | D16: =COUNTIFS(Experiments!$D$2:$D$83,$A16,Experiments!$L$2:$L$83,"Systemic",Experiments!$T$2:$T$83,"yes") -> 1 | E16: =COUNTIFS(Experiments!$D$2:$D$83,$A16,Experiments!$L$2:$L$83,"Intravitreal",Experiments!$T$2:$T$83,"yes") -> 0 | F16: =COUNTIFS(Experiments!$D$2:$D$83,$A16,Experiments!$L$2:$L$83,"Topical",Experiments!$T$2:$T$83,"yes") -> 0 | G16: =COUNTIFS(Experiments!$D$2:$D$83,$A16,Experiments!$L$2:$L$83,"Periocular",Experiments!$T$2:$T$83,"yes") -> 0 | H16: =COUNTIFS(Experiments!$D$2:$D$83,$A16,Experiments!$L$2:$L$83,"Combined",Experiments!$T$2:$T$83,"yes") -> 0 | I16: =COUNTIFS(Experiments!$D$2:$D$83,$A16,Experiments!$K$2:$K$83,"Acute injury",Experiments!$T$2:$T$83,"yes") -> 0 | J16: =COUNTIFS(Experiments!$D$2:$D$83,$A16,Experiments!$K$2:$K$83,"Induced OHT",Experiments!$T$2:$T$83,"yes") -> 0 | K16: =COUNTIFS(Experiments!$D$2:$D$83,$A16,Experiments!$K$2:$K$83,"Genetic / metabolic",Experiments!$T$2:$T$83,"yes") -> 1 | L16: =COUNTIFS(Experiments!$D$2:$D$83,$A16,Experiments!$O$2:$O$83,"Single dose",Experiments!$T$2:$T$83,"yes") -> 0 | M16: =COUNTIFS(Experiments!$D$2:$D$83,$A16,Experiments!$N$2:$N$83,">1",Experiments!$T$2:$T$83,"yes") -> 1 | N16: =COUNTIFS(Experiments!$D$2:$D$83,$A16,Experiments!$O$2:$O$83,"Not reported",Experiments!$T$2:$T$83,"yes") -> 0
A17: RIPK1/3 | B17: =INDEX('Drug classes'!$B$2:$B$20,MATCH(A17,'Drug classes'!$A$2:$A$20,0)) -> TNF / RIPK / MAPK | C17: =COUNTIFS(Experiments!$D$2:$D$83,A17,Experiments!$T$2:$T$83,"yes") -> 4 | D17: =COUNTIFS(Experiments!$D$2:$D$83,$A17,Experiments!$L$2:$L$83,"Systemic",Experiments!$T$2:$T$83,"yes") -> 1 | E17: =COUNTIFS(Experiments!$D$2:$D$83,$A17,Experiments!$L$2:$L$83,"Intravitreal",Experiments!$T$2:$T$83,"yes") -> 3 | F17: =COUNTIFS(Experiments!$D$2:$D$83,$A17,Experiments!$L$2:$L$83,"Topical",Experiments!$T$2:$T$83,"yes") -> 0 | G17: =COUNTIFS(Experiments!$D$2:$D$83,$A17,Experiments!$L$2:$L$83,"Periocular",Experiments!$T$2:$T$83,"yes") -> 0 | H17: =COUNTIFS(Experiments!$D$2:$D$83,$A17,Experiments!$L$2:$L$83,"Combined",Experiments!$T$2:$T$83,"yes") -> 0 | I17: =COUNTIFS(Experiments!$D$2:$D$83,$A17,Experiments!$K$2:$K$83,"Acute injury",Experiments!$T$2:$T$83,"yes") -> 4 | J17: =COUNTIFS(Experiments!$D$2:$D$83,$A17,Experiments!$K$2:$K$83,"Induced OHT",Experiments!$T$2:$T$83,"yes") -> 0 | K17: =COUNTIFS(Experiments!$D$2:$D$83,$A17,Experiments!$K$2:$K$83,"Genetic / metabolic",Experiments!$T$2:$T$83,"yes") -> 0 | L17: =COUNTIFS(Experiments!$D$2:$D$83,$A17,Experiments!$O$2:$O$83,"Single dose",Experiments!$T$2:$T$83,"yes") -> 4 | M17: =COUNTIFS(Experiments!$D$2:$D$83,$A17,Experiments!$N$2:$N$83,">1",Experiments!$T$2:$T$83,"yes") -> 0 | N17: =COUNTIFS(Experiments!$D$2:$D$83,$A17,Experiments!$O$2:$O$83,"Not reported",Experiments!$T$2:$T$83,"yes") -> 0
A18: p38 MAPK | B18: =INDEX('Drug classes'!$B$2:$B$20,MATCH(A18,'Drug classes'!$A$2:$A$20,0)) -> TNF / RIPK / MAPK | C18: =COUNTIFS(Experiments!$D$2:$D$83,A18,Experiments!$T$2:$T$83,"yes") -> 4 | D18: =COUNTIFS(Experiments!$D$2:$D$83,$A18,Experiments!$L$2:$L$83,"Systemic",Experiments!$T$2:$T$83,"yes") -> 1 | E18: =COUNTIFS(Experiments!$D$2:$D$83,$A18,Experiments!$L$2:$L$83,"Intravitreal",Experiments!$T$2:$T$83,"yes") -> 0 | F18: =COUNTIFS(Experiments!$D$2:$D$83,$A18,Experiments!$L$2:$L$83,"Topical",Experiments!$T$2:$T$83,"yes") -> 3 | G18: =COUNTIFS(Experiments!$D$2:$D$83,$A18,Experiments!$L$2:$L$83,"Periocular",Experiments!$T$2:$T$83,"yes") -> 0 | H18: =COUNTIFS(Experiments!$D$2:$D$83,$A18,Experiments!$L$2:$L$83,"Combined",Experiments!$T$2:$T$83,"yes") -> 0 | I18: =COUNTIFS(Experiments!$D$2:$D$83,$A18,Experiments!$K$2:$K$83,"Acute injury",Experiments!$T$2:$T$83,"yes") -> 0 | J18: =COUNTIFS(Experiments!$D$2:$D$83,$A18,Experiments!$K$2:$K$83,"Induced OHT",Experiments!$T$2:$T$83,"yes") -> 3 | K18: =COUNTIFS(Experiments!$D$2:$D$83,$A18,Experiments!$K$2:$K$83,"Genetic / metabolic",Experiments!$T$2:$T$83,"yes") -> 1 | L18: =COUNTIFS(Experiments!$D$2:$D$83,$A18,Experiments!$O$2:$O$83,"Single dose",Experiments!$T$2:$T$83,"yes") -> 0 | M18: =COUNTIFS(Experiments!$D$2:$D$83,$A18,Experiments!$N$2:$N$83,">1",Experiments!$T$2:$T$83,"yes") -> 4 | N18: =COUNTIFS(Experiments!$D$2:$D$83,$A18,Experiments!$O$2:$O$83,"Not reported",Experiments!$T$2:$T$83,"yes") -> 0
A19: JNK | B19: =INDEX('Drug classes'!$B$2:$B$20,MATCH(A19,'Drug classes'!$A$2:$A$20,0)) -> TNF / RIPK / MAPK | C19: =COUNTIFS(Experiments!$D$2:$D$83,A19,Experiments!$T$2:$T$83,"yes") -> 3 | D19: =COUNTIFS(Experiments!$D$2:$D$83,$A19,Experiments!$L$2:$L$83,"Systemic",Experiments!$T$2:$T$83,"yes") -> 3 | E19: =COUNTIFS(Experiments!$D$2:$D$83,$A19,Experiments!$L$2:$L$83,"Intravitreal",Experiments!$T$2:$T$83,"yes") -> 0 | F19: =COUNTIFS(Experiments!$D$2:$D$83,$A19,Experiments!$L$2:$L$83,"Topical",Experiments!$T$2:$T$83,"yes") -> 0 | G19: =COUNTIFS(Experiments!$D$2:$D$83,$A19,Experiments!$L$2:$L$83,"Periocular",Experiments!$T$2:$T$83,"yes") -> 0 | H19: =COUNTIFS(Experiments!$D$2:$D$83,$A19,Experiments!$L$2:$L$83,"Combined",Experiments!$T$2:$T$83,"yes") -> 0 | I19: =COUNTIFS(Experiments!$D$2:$D$83,$A19,Experiments!$K$2:$K$83,"Acute injury",Experiments!$T$2:$T$83,"yes") -> 3 | J19: =COUNTIFS(Experiments!$D$2:$D$83,$A19,Experiments!$K$2:$K$83,"Induced OHT",Experiments!$T$2:$T$83,"yes") -> 0 | K19: =COUNTIFS(Experiments!$D$2:$D$83,$A19,Experiments!$K$2:$K$83,"Genetic / metabolic",Experiments!$T$2:$T$83,"yes") -> 0 | L19: =COUNTIFS(Experiments!$D$2:$D$83,$A19,Experiments!$O$2:$O$83,"Single dose",Experiments!$T$2:$T$83,"yes") -> 1 | M19: =COUNTIFS(Experiments!$D$2:$D$83,$A19,Experiments!$N$2:$N$83,">1",Experiments!$T$2:$T$83,"yes") -> 2 | N19: =COUNTIFS(Experiments!$D$2:$D$83,$A19,Experiments!$O$2:$O$83,"Not reported",Experiments!$T$2:$T$83,"yes") -> 0
A20: TLR4 | B20: =INDEX('Drug classes'!$B$2:$B$20,MATCH(A20,'Drug classes'!$A$2:$A$20,0)) -> TLR4 / IL-1R / NF-κB | C20: =COUNTIFS(Experiments!$D$2:$D$83,A20,Experiments!$T$2:$T$83,"yes") -> 3 | D20: =COUNTIFS(Experiments!$D$2:$D$83,$A20,Experiments!$L$2:$L$83,"Systemic",Experiments!$T$2:$T$83,"yes") -> 0 | E20: =COUNTIFS(Experiments!$D$2:$D$83,$A20,Experiments!$L$2:$L$83,"Intravitreal",Experiments!$T$2:$T$83,"yes") -> 3 | F20: =COUNTIFS(Experiments!$D$2:$D$83,$A20,Experiments!$L$2:$L$83,"Topical",Experiments!$T$2:$T$83,"yes") -> 0 | G20: =COUNTIFS(Experiments!$D$2:$D$83,$A20,Experiments!$L$2:$L$83,"Periocular",Experiments!$T$2:$T$83,"yes") -> 0 | H20: =COUNTIFS(Experiments!$D$2:$D$83,$A20,Experiments!$L$2:$L$83,"Combined",Experiments!$T$2:$T$83,"yes") -> 0 | I20: =COUNTIFS(Experiments!$D$2:$D$83,$A20,Experiments!$K$2:$K$83,"Acute injury",Experiments!$T$2:$T$83,"yes") -> 2 | J20: =COUNTIFS(Experiments!$D$2:$D$83,$A20,Experiments!$K$2:$K$83,"Induced OHT",Experiments!$T$2:$T$83,"yes") -> 1 | K20: =COUNTIFS(Experiments!$D$2:$D$83,$A20,Experiments!$K$2:$K$83,"Genetic / metabolic",Experiments!$T$2:$T$83,"yes") -> 0 | L20: =COUNTIFS(Experiments!$D$2:$D$83,$A20,Experiments!$O$2:$O$83,"Single dose",Experiments!$T$2:$T$83,"yes") -> 2 | M20: =COUNTIFS(Experiments!$D$2:$D$83,$A20,Experiments!$N$2:$N$83,">1",Experiments!$T$2:$T$83,"yes") -> 1 | N20: =COUNTIFS(Experiments!$D$2:$D$83,$A20,Experiments!$O$2:$O$83,"Not reported",Experiments!$T$2:$T$83,"yes") -> 0
A21: NF-κB | B21: =INDEX('Drug classes'!$B$2:$B$20,MATCH(A21,'Drug classes'!$A$2:$A$20,0)) -> TLR4 / IL-1R / NF-κB | C21: =COUNTIFS(Experiments!$D$2:$D$83,A21,Experiments!$T$2:$T$83,"yes") -> 6 | D21: =COUNTIFS(Experiments!$D$2:$D$83,$A21,Experiments!$L$2:$L$83,"Systemic",Experiments!$T$2:$T$83,"yes") -> 3 | E21: =COUNTIFS(Experiments!$D$2:$D$83,$A21,Experiments!$L$2:$L$83,"Intravitreal",Experiments!$T$2:$T$83,"yes") -> 3 | F21: =COUNTIFS(Experiments!$D$2:$D$83,$A21,Experiments!$L$2:$L$83,"Topical",Experiments!$T$2:$T$83,"yes") -> 0 | G21: =COUNTIFS(Experiments!$D$2:$D$83,$A21,Experiments!$L$2:$L$83,"Periocular",Experiments!$T$2:$T$83,"yes") -> 0 | H21: =COUNTIFS(Experiments!$D$2:$D$83,$A21,Experiments!$L$2:$L$83,"Combined",Experiments!$T$2:$T$83,"yes") -> 0 | I21: =COUNTIFS(Experiments!$D$2:$D$83,$A21,Experiments!$K$2:$K$83,"Acute injury",Experiments!$T$2:$T$83,"yes") -> 3 | J21: =COUNTIFS(Experiments!$D$2:$D$83,$A21,Experiments!$K$2:$K$83,"Induced OHT",Experiments!$T$2:$T$83,"yes") -> 1 | K21: =COUNTIFS(Experiments!$D$2:$D$83,$A21,Experiments!$K$2:$K$83,"Genetic / metabolic",Experiments!$T$2:$T$83,"yes") -> 2 | L21: =COUNTIFS(Experiments!$D$2:$D$83,$A21,Experiments!$O$2:$O$83,"Single dose",Experiments!$T$2:$T$83,"yes") -> 2 | M21: =COUNTIFS(Experiments!$D$2:$D$83,$A21,Experiments!$N$2:$N$83,">1",Experiments!$T$2:$T$83,"yes") -> 4 | N21: =COUNTIFS(Experiments!$D$2:$D$83,$A21,Experiments!$O$2:$O$83,"Not reported",Experiments!$T$2:$T$83,"yes") -> 0
A22: P2X7 | B22: =INDEX('Drug classes'!$B$2:$B$20,MATCH(A22,'Drug classes'!$A$2:$A$20,0)) -> P2X7 / NLRP3 | C22: =COUNTIFS(Experiments!$D$2:$D$83,A22,Experiments!$T$2:$T$83,"yes") -> 2 | D22: =COUNTIFS(Experiments!$D$2:$D$83,$A22,Experiments!$L$2:$L$83,"Systemic",Experiments!$T$2:$T$83,"yes") -> 0 | E22: =COUNTIFS(Experiments!$D$2:$D$83,$A22,Experiments!$L$2:$L$83,"Intravitreal",Experiments!$T$2:$T$83,"yes") -> 1 | F22: =COUNTIFS(Experiments!$D$2:$D$83,$A22,Experiments!$L$2:$L$83,"Topical",Experiments!$T$2:$T$83,"yes") -> 1 | G22: =COUNTIFS(Experiments!$D$2:$D$83,$A22,Experiments!$L$2:$L$83,"Periocular",Experiments!$T$2:$T$83,"yes") -> 0 | H22: =COUNTIFS(Experiments!$D$2:$D$83,$A22,Experiments!$L$2:$L$83,"Combined",Experiments!$T$2:$T$83,"yes") -> 0 | I22: =COUNTIFS(Experiments!$D$2:$D$83,$A22,Experiments!$K$2:$K$83,"Acute injury",Experiments!$T$2:$T$83,"yes") -> 0 | J22: =COUNTIFS(Experiments!$D$2:$D$83,$A22,Experiments!$K$2:$K$83,"Induced OHT",Experiments!$T$2:$T$83,"yes") -> 1 | K22: =COUNTIFS(Experiments!$D$2:$D$83,$A22,Experiments!$K$2:$K$83,"Genetic / metabolic",Experiments!$T$2:$T$83,"yes") -> 1 | L22: =COUNTIFS(Experiments!$D$2:$D$83,$A22,Experiments!$O$2:$O$83,"Single dose",Experiments!$T$2:$T$83,"yes") -> 0 | M22: =COUNTIFS(Experiments!$D$2:$D$83,$A22,Experiments!$N$2:$N$83,">1",Experiments!$T$2:$T$83,"yes") -> 1 | N22: =COUNTIFS(Experiments!$D$2:$D$83,$A22,Experiments!$O$2:$O$83,"Not reported",Experiments!$T$2:$T$83,"yes") -> 1
A23: NLRP3 / ASC | B23: =INDEX('Drug classes'!$B$2:$B$20,MATCH(A23,'Drug classes'!$A$2:$A$20,0)) -> P2X7 / NLRP3 | C23: =COUNTIFS(Experiments!$D$2:$D$83,A23,Experiments!$T$2:$T$83,"yes") -> 4 | D23: =COUNTIFS(Experiments!$D$2:$D$83,$A23,Experiments!$L$2:$L$83,"Systemic",Experiments!$T$2:$T$83,"yes") -> 1 | E23: =COUNTIFS(Experiments!$D$2:$D$83,$A23,Experiments!$L$2:$L$83,"Intravitreal",Experiments!$T$2:$T$83,"yes") -> 3 | F23: =COUNTIFS(Experiments!$D$2:$D$83,$A23,Experiments!$L$2:$L$83,"Topical",Experiments!$T$2:$T$83,"yes") -> 0 | G23: =COUNTIFS(Experiments!$D$2:$D$83,$A23,Experiments!$L$2:$L$83,"Periocular",Experiments!$T$2:$T$83,"yes") -> 0 | H23: =COUNTIFS(Experiments!$D$2:$D$83,$A23,Experiments!$L$2:$L$83,"Combined",Experiments!$T$2:$T$83,"yes") -> 0 | I23: =COUNTIFS(Experiments!$D$2:$D$83,$A23,Experiments!$K$2:$K$83,"Acute injury",Experiments!$T$2:$T$83,"yes") -> 2 | J23: =COUNTIFS(Experiments!$D$2:$D$83,$A23,Experiments!$K$2:$K$83,"Induced OHT",Experiments!$T$2:$T$83,"yes") -> 0 | K23: =COUNTIFS(Experiments!$D$2:$D$83,$A23,Experiments!$K$2:$K$83,"Genetic / metabolic",Experiments!$T$2:$T$83,"yes") -> 2 | L23: =COUNTIFS(Experiments!$D$2:$D$83,$A23,Experiments!$O$2:$O$83,"Single dose",Experiments!$T$2:$T$83,"yes") -> 3 | M23: =COUNTIFS(Experiments!$D$2:$D$83,$A23,Experiments!$N$2:$N$83,">1",Experiments!$T$2:$T$83,"yes") -> 1 | N23: =COUNTIFS(Experiments!$D$2:$D$83,$A23,Experiments!$O$2:$O$83,"Not reported",Experiments!$T$2:$T$83,"yes") -> 0
A24: JAK/STAT3 | B24: =INDEX('Drug classes'!$B$2:$B$20,MATCH(A24,'Drug classes'!$A$2:$A$20,0)) -> IL-6 / JAK-STAT3 | C24: =COUNTIFS(Experiments!$D$2:$D$83,A24,Experiments!$T$2:$T$83,"yes") -> 2 | D24: =COUNTIFS(Experiments!$D$2:$D$83,$A24,Experiments!$L$2:$L$83,"Systemic",Experiments!$T$2:$T$83,"yes") -> 2 | E24: =COUNTIFS(Experiments!$D$2:$D$83,$A24,Experiments!$L$2:$L$83,"Intravitreal",Experiments!$T$2:$T$83,"yes") -> 0 | F24: =COUNTIFS(Experiments!$D$2:$D$83,$A24,Experiments!$L$2:$L$83,"Topical",Experiments!$T$2:$T$83,"yes") -> 0 | G24: =COUNTIFS(Experiments!$D$2:$D$83,$A24,Experiments!$L$2:$L$83,"Periocular",Experiments!$T$2:$T$83,"yes") -> 0 | H24: =COUNTIFS(Experiments!$D$2:$D$83,$A24,Experiments!$L$2:$L$83,"Combined",Experiments!$T$2:$T$83,"yes") -> 0 | I24: =COUNTIFS(Experiments!$D$2:$D$83,$A24,Experiments!$K$2:$K$83,"Acute injury",Experiments!$T$2:$T$83,"yes") -> 1 | J24: =COUNTIFS(Experiments!$D$2:$D$83,$A24,Experiments!$K$2:$K$83,"Induced OHT",Experiments!$T$2:$T$83,"yes") -> 1 | K24: =COUNTIFS(Experiments!$D$2:$D$83,$A24,Experiments!$K$2:$K$83,"Genetic / metabolic",Experiments!$T$2:$T$83,"yes") -> 0 | L24: =COUNTIFS(Experiments!$D$2:$D$83,$A24,Experiments!$O$2:$O$83,"Single dose",Experiments!$T$2:$T$83,"yes") -> 0 | M24: =COUNTIFS(Experiments!$D$2:$D$83,$A24,Experiments!$N$2:$N$83,">1",Experiments!$T$2:$T$83,"yes") -> 2 | N24: =COUNTIFS(Experiments!$D$2:$D$83,$A24,Experiments!$O$2:$O$83,"Not reported",Experiments!$T$2:$T$83,"yes") -> 0
A25: Glial inhibition | B25: =INDEX('Drug classes'!$B$2:$B$20,MATCH(A25,'Drug classes'!$A$2:$A$20,0)) -> Broad anti-inflammatory | C25: =COUNTIFS(Experiments!$D$2:$D$83,A25,Experiments!$T$2:$T$83,"yes") -> 7 | D25: =COUNTIFS(Experiments!$D$2:$D$83,$A25,Experiments!$L$2:$L$83,"Systemic",Experiments!$T$2:$T$83,"yes") -> 6 | E25: =COUNTIFS(Experiments!$D$2:$D$83,$A25,Experiments!$L$2:$L$83,"Intravitreal",Experiments!$T$2:$T$83,"yes") -> 1 | F25: =COUNTIFS(Experiments!$D$2:$D$83,$A25,Experiments!$L$2:$L$83,"Topical",Experiments!$T$2:$T$83,"yes") -> 0 | G25: =COUNTIFS(Experiments!$D$2:$D$83,$A25,Experiments!$L$2:$L$83,"Periocular",Experiments!$T$2:$T$83,"yes") -> 0 | H25: =COUNTIFS(Experiments!$D$2:$D$83,$A25,Experiments!$L$2:$L$83,"Combined",Experiments!$T$2:$T$83,"yes") -> 0 | I25: =COUNTIFS(Experiments!$D$2:$D$83,$A25,Experiments!$K$2:$K$83,"Acute injury",Experiments!$T$2:$T$83,"yes") -> 4 | J25: =COUNTIFS(Experiments!$D$2:$D$83,$A25,Experiments!$K$2:$K$83,"Induced OHT",Experiments!$T$2:$T$83,"yes") -> 2 | K25: =COUNTIFS(Experiments!$D$2:$D$83,$A25,Experiments!$K$2:$K$83,"Genetic / metabolic",Experiments!$T$2:$T$83,"yes") -> 1 | L25: =COUNTIFS(Experiments!$D$2:$D$83,$A25,Experiments!$O$2:$O$83,"Single dose",Experiments!$T$2:$T$83,"yes") -> 2 | M25: =COUNTIFS(Experiments!$D$2:$D$83,$A25,Experiments!$N$2:$N$83,">1",Experiments!$T$2:$T$83,"yes") -> 5 | N25: =COUNTIFS(Experiments!$D$2:$D$83,$A25,Experiments!$O$2:$O$83,"Not reported",Experiments!$T$2:$T$83,"yes") -> 0
... A32: Antibiotic | B32: =INDEX('Drug classes'!$B$2:$B$20,MATCH(A32,'Drug classes'!$A$2:$A$20,0)) -> Broad anti-inflammatory | C32: =COUNTIFS(Experiments!$D$2:$D$83,A32,Experiments!$T$2:$T$83,"yes") -> 3 | D32: =COUNTIFS(Experiments!$D$2:$D$83,$A32,Experiments!$L$2:$L$83,"Systemic",Experiments!$T$2:$T$83,"yes") -> 3 | E32: =COUNTIFS(Experiments!$D$2:$D$83,$A32,Experiments!$L$2:$L$83,"Intravitreal",Experiments!$T$2:$T$83,"yes") -> 0 | F32: =COUNTIFS(Experiments!$D$2:$D$83,$A32,Experiments!$L$2:$L$83,"Topical",Experiments!$T$2:$T$83,"yes") -> 0 | G32: =COUNTIFS(Experiments!$D$2:$D$83,$A32,Experiments!$L$2:$L$83,"Periocular",Experiments!$T$2:$T$83,"yes") -> 0 | H32: =COUNTIFS(Experiments!$D$2:$D$83,$A32,Experiments!$L$2:$L$83,"Combined",Experiments!$T$2:$T$83,"yes") -> 0 | I32: =COUNTIFS(Experiments!$D$2:$D$83,$A32,Experiments!$K$2:$K$83,"Acute injury",Experiments!$T$2:$T$83,"yes") -> 2 | J32: =COUNTIFS(Experiments!$D$2:$D$83,$A32,Experiments!$K$2:$K$83,"Induced OHT",Experiments!$T$2:$T$83,"yes") -> 1 | K32: =COUNTIFS(Experiments!$D$2:$D$83,$A32,Experiments!$K$2:$K$83,"Genetic / metabolic",Experiments!$T$2:$T$83,"yes") -> 0 | L32: =COUNTIFS(Experiments!$D$2:$D$83,$A32,Experiments!$O$2:$O$83,"Single dose",Experiments!$T$2:$T$83,"yes") -> 3 | M32: =COUNTIFS(Experiments!$D$2:$D$83,$A32,Experiments!$N$2:$N$83,">1",Experiments!$T$2:$T$83,"yes") -> 0 | N32: =COUNTIFS(Experiments!$D$2:$D$83,$A32,Experiments!$O$2:$O$83,"Not reported",Experiments!$T$2:$T$83,"yes") -> 0
A33: Total | C33: =SUM(C14:C32) -> 80 | D33: =SUM(D14:D32) -> 46 | E33: =SUM(E14:E32) -> 25 | F33: =SUM(F14:F32) -> 6 | G33: =SUM(G14:G32) -> 2 | H33: =SUM(H14:H32) -> 1 | I33: =SUM(I14:I32) -> 51 | J33: =SUM(J14:J32) -> 19 | ... N33: =SUM(N14:N32) -> 1
A34: Each row must add up: routes, model categories and dosing groups each sum to the Experiments column.

Sheet Experiments
A1: ID | B1: Compound | C1: Compound (base name) | D1: Drug class | E1: Pathway (Figure 2 branch) | F1: Manuscript table | G1: Reference | H1: Species | I1: Model (as reported) | J1: Injury model (grouped) | K1: Model category | L1: Route | M1: Route detail | N1: Treatment duration (days) | O1: Dosing group | P1: Readout day | Q1: RGC outcome | R1: In Tables 1–3 | S1: Include in figure | T1: In wheel
A2: 1 | B2: Etanercept | C2: Etanercept | D2: TNF-α | E2: =INDEX('Drug classes'!$B$2:$B$20,MATCH(D2,'Drug classes'!$A$2:$A$20,0)) -> TNF / RIPK / MAPK | F2: 1 | G2: 55 | H2: Rat | I2: Episcleral vein cauterization OHT | J2: Episcleral vein OHT | K2: Induced OHT | L2: Systemic | M2: s.c. 0.3 or 1 mg/kg 3x/week from day 1 until sacrifice | N2: 28 | O2: =IF(N2="","Not reported",IF(N2<=1,"Single dose",IF(N2<=7,"2–7 days",IF(N2<=28,"8–28 days",IF(N2<=90,"1–3 months","> 3 months"))))) -> 8–28 days | P2: 28 | Q2: Protective | R2: yes | S2: yes | T2: =IF(AND(R2="yes",S2="yes"),"yes","no") -> yes
A3: 2 | B3: Etanercept | C3: Etanercept | D3: TNF-α | E3: =INDEX('Drug classes'!$B$2:$B$20,MATCH(D3,'Drug classes'!$A$2:$A$20,0)) -> TNF / RIPK / MAPK | F3: 1 | G3: 56 | H3: Mouse | I3: Optic nerve crush | J3: Optic nerve crush | K3: Acute injury | L3: Systemic | M3: s.c. | N3: 7 | O3: =IF(N3="","Not reported",IF(N3<=1,"Single dose",IF(N3<=7,"2–7 days",IF(N3<=28,"8–28 days",IF(N3<=90,"1–3 months","> 3 months"))))) -> 2–7 days | P3: 14 | Q3: Protective | R3: yes | S3: yes | T3: =IF(AND(R3="yes",S3="yes"),"yes","no") -> yes
A4: 3 | B4: Etanercept | C4: Etanercept | D4: TNF-α | E4: =INDEX('Drug classes'!$B$2:$B$20,MATCH(D4,'Drug classes'!$A$2:$A$20,0)) -> TNF / RIPK / MAPK | F4: 1 | G4: 56 | H4: Mouse | I4: Sonication-induced traumatic optic neuropathy | J4: Traumatic optic neuropathy (sonication) | K4: Acute injury | L4: Systemic | M4: s.c. | N4: 7 | O4: =IF(N4="","Not reported",IF(N4<=1,"Single dose",IF(N4<=7,"2–7 days",IF(N4<=28,"8–28 days",IF(N4<=90,"1–3 months","> 3 months"))))) -> 2–7 days | P4: 28 | Q4: Protective | R4: no | S4: yes | T4: =IF(AND(R4="yes",S4="yes"),"yes","no") -> no
A5: 4 | B5: Etanercept | C5: Etanercept | D5: TNF-α | E5: =INDEX('Drug classes'!$B$2:$B$20,MATCH(D5,'Drug classes'!$A$2:$A$20,0)) -> TNF / RIPK / MAPK | F5: 1 | G5: 57 | H5: Rat | I5: Retinal ischemia (high IOP) | J5: Retinal ischemia / acute IOP elevation | K5: Acute injury | L5: Systemic | M5: s.c. | N5: 28 | O5: =IF(N5="","Not reported",IF(N5<=1,"Single dose",IF(N5<=7,"2–7 days",IF(N5<=28,"8–28 days",IF(N5<=90,"1–3 months","> 3 months"))))) -> 8–28 days | P5: 28 | Q5: Protective | R5: yes | S5: yes | T5: =IF(AND(R5="yes",S5="yes"),"yes","no") -> yes
A6: 5 | B6: Infliximab | C6: Infliximab | D6: TNF-α | E6: =INDEX('Drug classes'!$B$2:$B$20,MATCH(D6,'Drug classes'!$A$2:$A$20,0)) -> TNF / RIPK / MAPK | F6: 1 | G6: 58 | H6: Mouse | I6: Corneal alkali burn | J6: Corneal alkali burn | K6: Acute injury | L6: Systemic | M6: i.p. | N6: 1 | O6: =IF(N6="","Not reported",IF(N6<=1,"Single dose",IF(N6<=7,"2–7 days",IF(N6<=28,"8–28 days",IF(N6<=90,"1–3 months","> 3 months"))))) -> Single dose | Q6: Protective | R6: yes | S6: yes | T6: =IF(AND(R6="yes",S6="yes"),"yes","no") -> yes
A7: 6 | B7: Infliximab | C7: Infliximab | D7: TNF-α | E7: =INDEX('Drug classes'!$B$2:$B$20,MATCH(D7,'Drug classes'!$A$2:$A$20,0)) -> TNF / RIPK / MAPK | F7: 1 | G7: 59 | H7: Mouse | I7: Corneal alkali burn | J7: Corneal alkali burn | K7: Acute injury | L7: Systemic | M7: i.p. | N7: 1 | O7: =IF(N7="","Not reported",IF(N7<=1,"Single dose",IF(N7<=7,"2–7 days",IF(N7<=28,"8–28 days",IF(N7<=90,"1–3 months","> 3 months"))))) -> Single dose | P7: 1 | Q7: Protective | R7: yes | S7: yes | T7: =IF(AND(R7="yes",S7="yes"),"yes","no") -> yes
A8: 7 | B8: Infliximab | C8: Infliximab | D8: TNF-α | E8: =INDEX('Drug classes'!$B$2:$B$20,MATCH(D8,'Drug classes'!$A$2:$A$20,0)) -> TNF / RIPK / MAPK | F8: 1 | G8: 59 | H8: Rabbit | I8: Corneal alkali burn | J8: Corneal alkali burn | K8: Acute injury | L8: Systemic | M8: i.v. | N8: 1 | O8: =IF(N8="","Not reported",IF(N8<=1,"Single dose",IF(N8<=7,"2–7 days",IF(N8<=28,"8–28 days",IF(N8<=90,"1–3 months","> 3 months"))))) -> Single dose | Q8: Protective | R8: yes | S8: yes | T8: =IF(AND(R8="yes",S8="yes"),"yes","no") -> yes
A9: 8 | B9: Adalimumab | C9: Adalimumab | D9: TNF-α | E9: =INDEX('Drug classes'!$B$2:$B$20,MATCH(D9,'Drug classes'!$A$2:$A$20,0)) -> TNF / RIPK / MAPK | F9: 1 | G9: 60 | H9: Rabbit | I9: Corneal alkali burn | J9: Corneal alkali burn | K9: Acute injury | L9: Periocular | M9: subconjunctival | N9: 1 | O9: =IF(N9="","Not reported",IF(N9<=1,"Single dose",IF(N9<=7,"2–7 days",IF(N9<=28,"8–28 days",IF(N9<=90,"1–3 months","> 3 months"))))) -> Single dose | P9: 90 | Q9: Protective | R9: yes | S9: yes | T9: =IF(AND(R9="yes",S9="yes"),"yes","no") -> yes
A10: 9 | B10: XPro1595 | C10: XPro1595 | D10: TNF-α | E10: =INDEX('Drug classes'!$B$2:$B$20,MATCH(D10,'Drug classes'!$A$2:$A$20,0)) -> TNF / RIPK / MAPK | F10: 1 | G10: 49 | H10: Rat | I10: Hypertonic saline episcleral vein OHT | J10: Hypertonic saline OHT | K10: Induced OHT | L10: Intravitreal | M10: intravitreal 5 uL (50 ug/uL) at 1 and 2 weeks after OHT induction; RGCs at 3 weeks | N10: 8 | O10: =IF(N10="","Not reported",IF(N10<=1,"Single dose",IF(N10<=7,"2–7 days",IF(N10<=28,"8–28 days",IF(N10<=90,"1–3 months","> 3 months"))))) -> 8–28 days | P10: 21 | Q10: Protective | R10: yes | S10: yes | T10: =IF(AND(R10="yes",S10="yes"),"yes","no") -> yes
A11: 10 | B11: R7050 | C11: R7050 | D11: TNF-α | E11: =INDEX('Drug classes'!$B$2:$B$20,MATCH(D11,'Drug classes'!$A$2:$A$20,0)) -> TNF / RIPK / MAPK | F11: 1 | G11: 62 | H11: Mouse | I11: Optic nerve crush | J11: Optic nerve crush | K11: Acute injury | L11: Systemic | M11: i.p. daily | N11: 14 | O11: =IF(N11="","Not reported",IF(N11<=1,"Single dose",IF(N11<=7,"2–7 days",IF(N11<=28,"8–28 days",IF(N11<=90,"1–3 months","> 3 months"))))) -> 8–28 days | P11: 14 | Q11: Protective | R11: yes | S11: yes | T11: =IF(AND(R11="yes",S11="yes"),"yes","no") -> yes
A12: 11 | B12: R7050 | C12: R7050 | D12: TNF-α | E12: =INDEX('Drug classes'!$B$2:$B$20,MATCH(D12,'Drug classes'!$A$2:$A$20,0)) -> TNF / RIPK / MAPK | F12: 1 | G12: 62 | H12: Mouse | I12: Optic nerve crush | J12: Optic nerve crush | K12: Acute injury | L12: Intravitreal | M12: single injection | N12: 1 | O12: =IF(N12="","Not reported",IF(N12<=1,"Single dose",IF(N12<=7,"2–7 days",IF(N12<=28,"8–28 days",IF(N12<=90,"1–3 months","> 3 months"))))) -> Single dose | P12: 14 | Q12: Protective | R12: yes | S12: yes | T12: =IF(AND(R12="yes",S12="yes"),"yes","no") -> yes
A13: 12 | B13: R7050 | C13: R7050 | D13: TNF-α | E13: =INDEX('Drug classes'!$B$2:$B$20,MATCH(D13,'Drug classes'!$A$2:$A$20,0)) -> TNF / RIPK / MAPK | F13: 1 | G13: 62 | H13: Mouse | I13: Optic nerve crush | J13: Optic nerve crush | K13: Acute injury | L13: Combined | M13: i.p. daily + single intravitreal | N13: 5 | O13: =IF(N13="","Not reported",IF(N13<=1,"Single dose",IF(N13<=7,"2–7 days",IF(N13<=28,"8–28 days",IF(N13<=90,"1–3 months","> 3 months"))))) -> 2–7 days | P13: 5 | Q13: Protective | R13: yes | S13: yes | T13: =IF(AND(R13="yes",S13="yes"),"yes","no") -> yes
A14: 13 | B14: IL-1Ra | C14: IL-1Ra | D14: IL-1β | E14: =INDEX('Drug classes'!$B$2:$B$20,MATCH(D14,'Drug classes'!$A$2:$A$20,0)) -> TLR4 / IL-1R / NF-κB | F14: 1 | G14: 71 | H14: Rat | I14: Retinal ischemia/reperfusion (high IOP) | J14: Retinal ischemia / acute IOP elevation | K14: Acute injury | L14: Intravitreal | M14: single injection 5 min before ischemia | N14: 1 | O14: =IF(N14="","Not reported",IF(N14<=1,"Single dose",IF(N14<=7,"2–7 days",IF(N14<=28,"8–28 days",IF(N14<=90,"1–3 months","> 3 months"))))) -> Single dose | P14: 7 | Q14: Protective | R14: yes | S14: yes | T14: =IF(AND(R14="yes",S14="yes"),"yes","no") -> yes
A15: 14 | B15: Anakinra | C15: Anakinra | D15: IL-1β | E15: =INDEX('Drug classes'!$B$2:$B$20,MATCH(D15,'Drug classes'!$A$2:$A$20,0)) -> TLR4 / IL-1R / NF-κB | F15: 1 | G15: 72 | H15: Mouse | I15: Blast traumatic brain injury | J15: Blast traumatic brain injury | K15: Acute injury | L15: Systemic | M15: i.p. daily (day -7 to +21) | N15: 29 | O15: =IF(N15="","Not reported",IF(N15<=1,"Single dose",IF(N15<=7,"2–7 days",IF(N15<=28,"8–28 days",IF(N15<=90,"1–3 months","> 3 months"))))) -> 1–3 months | P15: 28 | Q15: Protective | R15: yes | S15: yes | T15: =IF(AND(R15="yes",S15="yes"),"yes","no") -> yes
A16: 15 | B16: sgp130Fc | C16: sgp130Fc | D16: IL-6 | E16: =INDEX('Drug classes'!$B$2:$B$20,MATCH(D16,'Drug classes'!$A$2:$A$20,0)) -> IL-6 / JAK-STAT3 | F16: 1 | G16: 80 | H16: Mouse | I16: STZ diabetes | J16: STZ diabetes | K16: Genetic / metabolic | L16: Systemic | M16: i.p. twice weekly x 2 weeks | N16: 14 | O16: =IF(N16="","Not reported",IF(N16<=1,"Single dose",IF(N16<=7,"2–7 days",IF(N16<=28,"8–28 days",IF(N16<=90,"1–3 months","> 3 months"))))) -> 8–28 days | Q16: No RGC readout | R16: yes | S16: yes | T16: =IF(AND(R16="yes",S16="yes"),"yes","no") -> yes
A17: 16 | B17: BAY 11-7082 | C17: BAY 11-7082 | D17: NF-κB | E17: =INDEX('Drug classes'!$B$2:$B$20,MATCH(D17,'Drug classes'!$A$2:$A$20,0)) -> TLR4 / IL-1R / NF-κB | F17: 2 | G17: 83 | H17: Rat | I17: NMDA intravitreal | J17: NMDA excitotoxicity | K17: Acute injury | L17: Intravitreal | M17: co-injected with NMDA | N17: 1 | O17: =IF(N17="","Not reported",IF(N17<=1,"Single dose",IF(N17<=7,"2–7 days",IF(N17<=28,"8–28 days",IF(N17<=90,"1–3 months","> 3 months"))))) -> Single dose | P17: 7 | Q17: Protective | R17: yes | S17: yes | T17: =IF(AND(R17="yes",S17="yes"),"yes","no") -> yes
A18: 17 | B18: IMD-0354 | C18: IMD-0354 | D18: NF-κB | E18: =INDEX('Drug classes'!$B$2:$B$20,MATCH(D18,'Drug classes'!$A$2:$A$20,0)) -> TLR4 / IL-1R / NF-κB | F18: 2 | G18: 83 | H18: Rat | I18: NMDA intravitreal | J18: NMDA excitotoxicity | K18: Acute injury | L18: Intravitreal | M18: co-injected with NMDA | N18: 1 | O18: =IF(N18="","Not reported",IF(N18<=1,"Single dose",IF(N18<=7,"2–7 days",IF(N18<=28,"8–28 days",IF(N18<=90,"1–3 months","> 3 months"))))) -> Single dose | P18: 7 | Q18: Protective | R18: yes | S18: yes | T18: =IF(AND(R18="yes",S18="yes"),"yes","no") -> yes
A19: 18 | B19: IMD-0354 | C19: IMD-0354 | D19: NF-κB | E19: =INDEX('Drug classes'!$B$2:$B$20,MATCH(D19,'Drug classes'!$A$2:$A$20,0)) -> TLR4 / IL-1R / NF-κB | F19: 2 | G19: 84 | H19: Rat | I19: STZ diabetes | J19: STZ diabetes | K19: Genetic / metabolic | L19: Systemic | M19: i.p. for 6 consecutive weeks | N19: 42 | O19: =IF(N19="","Not reported",IF(N19<=1,"Single dose",IF(N19<=7,"2–7 days",IF(N19<=28,"8–28 days",IF(N19<=90,"1–3 months","> 3 months"))))) -> 1–3 months | Q19: Partial | R19: yes | S19: yes | T19: =IF(AND(R19="yes",S19="yes"),"yes","no") -> yes
A20: 19 | B20: Puerarin | C20: Puerarin | D20: NF-κB | E20: =INDEX('Drug classes'!$B$2:$B$20,MATCH(D20,'Drug classes'!$A$2:$A$20,0)) -> TLR4 / IL-1R / NF-κB | F20: 2 | G20: 85 | H20: Mouse | I20: Col8a2-mutant neovascular glaucoma | J20: Col8a2 neovascular glaucoma | K20: Genetic / metabolic | L20: Intravitreal | M20: intraocular injection 0.2 mg/kg (site not specified; classed as intravitreal) | N20: 30 | O20: =IF(N20="","Not reported",IF(N20<=1,"Single dose",IF(N20<=7,"2–7 days",IF(N20<=28,"8–28 days",IF(N20<=90,"1–3 months","> 3 months"))))) -> 1–3 months | Q20: No RGC readout | R20: yes | S20: yes | T20: =IF(AND(R20="yes",S20="yes"),"yes","no") -> yes
A21: 20 | B21: NLY01 | C21: NLY01 | D21: NF-κB | E21: =INDEX('Drug classes'!$B$2:$B$20,MATCH(D21,'Drug classes'!$A$2:$A$20,0)) -> TLR4 / IL-1R / NF-κB | F21: 2 | G21: 86 | H21: Mouse | I21: Microbead OHT | J21: Microbead OHT | K21: Induced OHT | L21: Systemic | M21: s.c. twice weekly | N21: 42 | O21: =IF(N21="","Not reported",IF(N21<=1,"Single dose",IF(N21<=7,"2–7 days",IF(N21<=28,"8–28 days",IF(N21<=90,"1–3 months","> 3 months"))))) -> 1–3 months | P21: 42 | Q21: Protective | R21: yes | S21: yes | T21: =IF(AND(R21="yes",S21="yes"),"yes","no") -> yes
A22: 21 | B22: Metformin | C22: Metformin | D22: NF-κB | E22: =INDEX('Drug classes'!$B$2:$B$20,MATCH(D22,'Drug classes'!$A$2:$A$20,0)) -> TLR4 / IL-1R / NF-κB | F22: 2 | G22: 87 | H22: Mouse | I22: Retinal ischemia/reperfusion (high IOP) | J22: Retinal ischemia / acute IOP elevation | K22: Acute injury | L22: Systemic | M22: i.p. 10 or 50 mg/kg once daily; ischemia on day 4 of treatment; continued to day 7 after | N22: 11 | O22: =IF(N22="","Not reported",IF(N22<=1,"Single dose",IF(N22<=7,"2–7 days",IF(N22<=28,"8–28 days",IF(N22<=90,"1–3 months","> 3 months"))))) -> 8–28 days | P22: 7 | Q22: Protective | R22: yes | S22: yes | T22: =IF(AND(R22="yes",S22="yes"),"yes","no") -> yes
A23: 22 | B23: BIRB 796 | C23: BIRB 796 | D23: p38 MAPK | E23: =INDEX('Drug classes'!$B$2:$B$20,MATCH(D23,'Drug classes'!$A$2:$A$20,0)) -> TNF / RIPK / MAPK | F23: 2 | G23: 88 | H23: Rat | I23: Microbead OHT | J23: Microbead OHT | K23: Induced OHT | L23: Topical | M23: eye drops twice daily Mon-Fri | N23: 28 | O23: =IF(N23="","Not reported",IF(N23<=1,"Single dose",IF(N23<=7,"2–7 days",IF(N23<=28,"8–28 days",IF(N23<=90,"1–3 months","> 3 months"))))) -> 8–28 days | P23: 28 | Q23: Protective | R23: yes | S23: yes | T23: =IF(AND(R23="yes",S23="yes"),"yes","no") -> yes
A24: 23 | B24: BIRB 796 | C24: BIRB 796 | D24: p38 MAPK | E24: =INDEX('Drug classes'!$B$2:$B$20,MATCH(D24,'Drug classes'!$A$2:$A$20,0)) -> TNF / RIPK / MAPK | F24: 2 | G24: 88 | H24: Mouse | I24: DBA/2J | J24: DBA/2J | K24: Genetic / metabolic | L24: Topical | M24: eye drops once daily Mon-Fri | N24: 168 | O24: =IF(N24="","Not reported",IF(N24<=1,"Single dose",IF(N24<=7,"2–7 days",IF(N24<=28,"8–28 days",IF(N24<=90,"1–3 months","> 3 months"))))) -> > 3 months | Q24: No protection | R24: yes | S24: yes | T24: =IF(AND(R24="yes",S24="yes"),"yes","no") -> yes
A25: 24 | B25: BIRB 796 | C25: BIRB 796 | D25: p38 MAPK | E25: =INDEX('Drug classes'!$B$2:$B$20,MATCH(D25,'Drug classes'!$A$2:$A$20,0)) -> TNF / RIPK / MAPK | F25: 2 | G25: 88 | H25: Squirrel monkey | I25: Microbead OHT | J25: Microbead OHT | K25: Induced OHT | L25: Topical | M25: eye drops once daily Mon-Fri | N25: 203 | O25: =IF(N25="","Not reported",IF(N25<=1,"Single dose",IF(N25<=7,"2–7 days",IF(N25<=28,"8–28 days",IF(N25<=90,"1–3 months","> 3 months"))))) -> > 3 months | P25: 203 | Q25: No protection | R25: no | S25: no | T25: =IF(AND(R25="yes",S25="yes"),"yes","no") -> no
A26: 25 | B26: GRGM-13 | C26: GRGM-13 | D26: p38 MAPK | E26: =INDEX('Drug classes'!$B$2:$B$20,MATCH(D26,'Drug classes'!$A$2:$A$20,0)) -> TNF / RIPK / MAPK | F26: 2 | G26: 90 | H26: Rat | I26: Hypertonic saline episcleral vein OHT | J26: Hypertonic saline OHT | K26: Induced OHT | L26: Systemic | M26: intragastric 0.4/0.8/1.6 g/kg/d, once daily x 9 days | N26: 9 | O26: =IF(N26="","Not reported",IF(N26<=1,"Single dose",IF(N26<=7,"2–7 days",IF(N26<=28,"8–28 days",IF(N26<=90,"1–3 months","> 3 months"))))) -> 8–28 days | Q26: Protective | R26: yes | S26: yes | T26: =IF(AND(R26="yes",S26="yes"),"yes","no") -> yes
A27: 26 | B27: Ro3206145 | C27: Ro3206145 | D27: p38 MAPK | E27: =INDEX('Drug classes'!$B$2:$B$20,MATCH(D27,'Drug classes'!$A$2:$A$20,0)) -> TNF / RIPK / MAPK | F27: 2 | G27: 91 | H27: Rat | I27: Microbead OHT | J27: Microbead OHT | K27: Induced OHT | L27: Topical | M27: eye drops twice daily | N27: 41 | O27: =IF(N27="","Not reported",IF(N27<=1,"Single dose",IF(N27<=7,"2–7 days",IF(N27<=28,"8–28 days",IF(N27<=90,"1–3 months","> 3 months"))))) -> 1–3 months | P27: 42 | Q27: Axonal only | R27: yes | S27: yes | T27: =IF(AND(R27="yes",S27="yes"),"yes","no") -> yes
A28: 27 | B28: SP600125 | C28: SP600125 | D28: JNK | E28: =INDEX('Drug classes'!$B$2:$B$20,MATCH(D28,'Drug classes'!$A$2:$A$20,0)) -> TNF / RIPK / MAPK | F28: 2 | G28: 103 | H28: Rat | I28: Acute moderate IOP elevation (6 h) | J28: Retinal ischemia / acute IOP elevation | K28: Acute injury | L28: Systemic | M28: systemic, given during 6-h IOP elevation (~45 mmHg) | N28: 1 | O28: =IF(N28="","Not reported",IF(N28<=1,"Single dose",IF(N28<=7,"2–7 days",IF(N28<=28,"8–28 days",IF(N28<=90,"1–3 months","> 3 months"))))) -> Single dose | P28: 0.25 | Q28: Not determined | R28: yes | S28: yes | T28: =IF(AND(R28="yes",S28="yes"),"yes","no") -> yes
A29: 28 | B29: SP600125 | C29: SP600125 | D29: JNK | E29: =INDEX('Drug classes'!$B$2:$B$20,MATCH(D29,'Drug classes'!$A$2:$A$20,0)) -> TNF / RIPK / MAPK | F29: 2 | G29: 104 | H29: Rat | I29: Acute moderate IOP elevation (7 h) | J29: Retinal ischemia / acute IOP elevation | K29: Acute injury | L29: Systemic | M29: i.p. 7 doses (days 0-7) | N29: 7 | O29: =IF(N29="","Not reported",IF(N29<=1,"Single dose",IF(N29<=7,"2–7 days",IF(N29<=28,"8–28 days",IF(N29<=90,"1–3 months","> 3 months"))))) -> 2–7 days | P29: 28 | Q29: Protective | R29: yes | S29: yes | T29: =IF(AND(R29="yes",S29="yes"),"yes","no") -> yes
A30: 29 | B30: MCC950 | C30: MCC950 | D30: NLRP3 / ASC | E30: =INDEX('Drug classes'!$B$2:$B$20,MATCH(D30,'Drug classes'!$A$2:$A$20,0)) -> P2X7 / NLRP3 | F30: 2 | G30: 92 | H30: Mouse | I30: OPTN(E50K) | J30: OPTN(E50K) | K30: Genetic / metabolic | L30: Intravitreal | M30: single injection | N30: 1 | O30: =IF(N30="","Not reported",IF(N30<=1,"Single dose",IF(N30<=7,"2–7 days",IF(N30<=28,"8–28 days",IF(N30<=90,"1–3 months","> 3 months"))))) -> Single dose | P30: 7 | Q30: Protective | R30: yes | S30: yes | T30: =IF(AND(R30="yes",S30="yes"),"yes","no") -> yes
A31: 30 | B31: MCC950 | C31: MCC950 | D31: NLRP3 / ASC | E31: =INDEX('Drug classes'!$B$2:$B$20,MATCH(D31,'Drug classes'!$A$2:$A$20,0)) -> P2X7 / NLRP3 | F31: 2 | G31: 93 | H31: Mouse | I31: STZ diabetes | J31: STZ diabetes | K31: Genetic / metabolic | L31: Intravitreal | M31: single intravitreal injection (2 uL) after diabetes induction | N31: 1 | O31: =IF(N31="","Not reported",IF(N31<=1,"Single dose",IF(N31<=7,"2–7 days",IF(N31<=28,"8–28 days",IF(N31<=90,"1–3 months","> 3 months"))))) -> Single dose | Q31: No RGC readout | R31: yes | S31: yes | T31: =IF(AND(R31="yes",S31="yes"),"yes","no") -> yes
A32: 31 | B32: IC-100 | C32: IC-100 | D32: NLRP3 / ASC | E32: =INDEX('Drug classes'!$B$2:$B$20,MATCH(D32,'Drug classes'!$A$2:$A$20,0)) -> P2X7 / NLRP3 | F32: 2 | G32: 94 | H32: Mouse | I32: Oxygen-induced retinopathy | J32: Oxygen-induced retinopathy | K32: Acute injury | L32: Intravitreal | M32: single injection at P12 | N32: 1 | O32: =IF(N32="","Not reported",IF(N32<=1,"Single dose",IF(N32<=7,"2–7 days",IF(N32<=28,"8–28 days",IF(N32<=90,"1–3 months","> 3 months"))))) -> Single dose | P32: 18 | Q32: No RGC readout | R32: yes | S32: yes | T32: =IF(AND(R32="yes",S32="yes"),"yes","no") -> yes
A33: 32 | B33: IC-100 | C33: IC-100 | D33: NLRP3 / ASC | E33: =INDEX('Drug classes'!$B$2:$B$20,MATCH(D33,'Drug classes'!$A$2:$A$20,0)) -> P2X7 / NLRP3 | F33: 2 | G33: 94 | H33: Mouse | I33: Oxygen-induced retinopathy | J33: Oxygen-induced retinopathy | K33: Acute injury | L33: Systemic | M33: i.p. P12/P14/P16 | N33: 5 | O33: =IF(N33="","Not reported",IF(N33<=1,"Single dose",IF(N33<=7,"2–7 days",IF(N33<=28,"8–28 days",IF(N33<=90,"1–3 months","> 3 months"))))) -> 2–7 days | P33: 18 | Q33: No RGC readout | R33: yes | S33: yes | T33: =IF(AND(R33="yes",S33="yes"),"yes","no") -> yes
A34: 33 | B34: TAK-242 | C34: TAK-242 | D34: TLR4 | E34: =INDEX('Drug classes'!$B$2:$B$20,MATCH(D34,'Drug classes'!$A$2:$A$20,0)) -> TLR4 / IL-1R / NF-κB | F34: 2 | G34: 95 | H34: Mouse | I34: Optic nerve crush | J34: Optic nerve crush | K34: Acute injury | L34: Intravitreal | M34: single injection | N34: 1 | O34: =IF(N34="","Not reported",IF(N34<=1,"Single dose",IF(N34<=7,"2–7 days",IF(N34<=28,"8–28 days",IF(N34<=90,"1–3 months","> 3 months"))))) -> Single dose | P34: 10 | Q34: Protective | R34: yes | S34: yes | T34: =IF(AND(R34="yes",S34="yes"),"yes","no") -> yes
A35: 34 | B35: C34 | C35: C34 | D35: TLR4 | E35: =INDEX('Drug classes'!$B$2:$B$20,MATCH(D35,'Drug classes'!$A$2:$A$20,0)) -> TLR4 / IL-1R / NF-κB | F35: 2 | G35: 95 | H35: Mouse | I35: Optic nerve crush | J35: Optic nerve crush | K35: Acute injury | L35: Intravitreal | M35: single injection | N35: 1 | O35: =IF(N35="","Not reported",IF(N35<=1,"Single dose",IF(N35<=7,"2–7 days",IF(N35<=28,"8–28 days",IF(N35<=90,"1–3 months","> 3 months"))))) -> Single dose | Q35: No RGC readout | R35: yes | S35: yes | T35: =IF(AND(R35="yes",S35="yes"),"yes","no") -> yes
A36: 35 | B36: TAK-242 | C36: TAK-242 | D36: TLR4 | E36: =INDEX('Drug classes'!$B$2:$B$20,MATCH(D36,'Drug classes'!$A$2:$A$20,0)) -> TLR4 / IL-1R / NF-κB | F36: 2 | G36: 96 | H36: Rat | I36: Hydrogel-induced OHT | J36: Hydrogel-induced OHT | K36: Induced OHT | L36: Intravitreal | M36: weekly from day -3 | N36: 31 | O36: =IF(N36="","Not reported",IF(N36<=1,"Single dose",IF(N36<=7,"2–7 days",IF(N36<=28,"8–28 days",IF(N36<=90,"1–3 months","> 3 months"))))) -> 1–3 months | P36: 28 | Q36: Protective | R36: yes | S36: yes | T36: =IF(AND(R36="yes",S36="yes"),"yes","no") -> yes
A37: 36 | B37: JNJ47965567 | C37: JNJ47965567 | D37: P2X7 | E37: =INDEX('Drug classes'!$B$2:$B$20,MATCH(D37,'Drug classes'!$A$2:$A$20,0)) -> P2X7 / NLRP3 | F37: 2 | G37: 97 | H37: Mouse | I37: DBA/2J | J37: DBA/2J | K37: Genetic / metabolic | L37: Topical | M37: chronic eye drops | N37: 154 | O37: =IF(N37="","Not reported",IF(N37<=1,"Single dose",IF(N37<=7,"2–7 days",IF(N37<=28,"8–28 days",IF(N37<=90,"1–3 months","> 3 months"))))) -> > 3 months | Q37: Protective | R37: yes | S37: yes | T37: =IF(AND(R37="yes",S37="yes"),"yes","no") -> yes
A38: 37 | B38: A740003 | C38: A740003 | D38: P2X7 | E38: =INDEX('Drug classes'!$B$2:$B$20,MATCH(D38,'Drug classes'!$A$2:$A$20,0)) -> P2X7 / NLRP3 | F38: 2 | G38: 98 | H38: Mouse | I38: Chronic OHT (method n.s.) | J38: Chronic OHT (method n.s.) | K38: Induced OHT | L38: Intravitreal | M38: pre-injection | O38: =IF(N38="","Not reported",IF(N38<=1,"Single dose",IF(N38<=7,"2–7 days",IF(N38<=28,"8–28 days",IF(N38<=90,"1–3 months","> 3 months"))))) -> Not reported | Q38: Partial | R38: yes | S38: yes | T38: =IF(AND(R38="yes",S38="yes"),"yes","no") -> yes
A39: 38 | B39: Ripa-56 | C39: Ripa-56 | D39: RIPK1/3 | E39: =INDEX('Drug classes'!$B$2:$B$20,MATCH(D39,'Drug classes'!$A$2:$A$20,0)) -> TNF / RIPK / MAPK | F39: 2 | G39: 100 | H39: Mouse | I39: NMDA intravitreal | J39: NMDA excitotoxicity | K39: Acute injury | L39: Intravitreal | M39: co-injected with NMDA | N39: 1 | O39: =IF(N39="","Not reported",IF(N39<=1,"Single dose",IF(N39<=7,"2–7 days",IF(N39<=28,"8–28 days",IF(N39<=90,"1–3 months","> 3 months"))))) -> Single dose | P39: 3 | Q39: Partial | R39: yes | S39: yes | T39: =IF(AND(R39="yes",S39="yes"),"yes","no") -> yes
A40: 39 | B40: Necrostatin-1 | C40: Necrostatin-1 | D40: RIPK1/3 | E40: =INDEX('Drug classes'!$B$2:$B$20,MATCH(D40,'Drug classes'!$A$2:$A$20,0)) -> TNF / RIPK / MAPK | F40: 2 | G40: 101 | H40: Mouse | I40: NMDA intravitreal | J40: NMDA excitotoxicity | K40: Acute injury | L40: Intravitreal | M40: co-injected with NMDA | N40: 1 | O40: =IF(N40="","Not reported",IF(N40<=1,"Single dose",IF(N40<=7,"2–7 days",IF(N40<=28,"8–28 days",IF(N40<=90,"1–3 months","> 3 months"))))) -> Single dose | P40: 5 | Q40: Protective | R40: yes | S40: yes | T40: =IF(AND(R40="yes",S40="yes"),"yes","no") -> yes
...

Sheet Drug classes
A1: Drug class | B1: Pathway (Figure 2 branch) | C1: Manuscript table | D1: Table group
A2: TNF-α | B2: TNF / RIPK / MAPK | C2: 1 | D2: Cytokine antagonists
A3: IL-1β | B3: TLR4 / IL-1R / NF-κB | C3: 1 | D3: Cytokine antagonists
A4: IL-6 | B4: IL-6 / JAK-STAT3 | C4: 1 | D4: Cytokine antagonists
A5: RIPK1/3 | B5: TNF / RIPK / MAPK | C5: 2 | D5: Pathway inhibitors
A6: p38 MAPK | B6: TNF / RIPK / MAPK | C6: 2 | D6: Pathway inhibitors
A7: JNK | B7: TNF / RIPK / MAPK | C7: 2 | D7: Pathway inhibitors
A8: TLR4 | B8: TLR4 / IL-1R / NF-κB | C8: 2 | D8: Pathway inhibitors
A9: NF-κB | B9: TLR4 / IL-1R / NF-κB | C9: 2 | D9: Pathway inhibitors
A10: P2X7 | B10: P2X7 / NLRP3 | C10: 2 | D10: Pathway inhibitors
A11: NLRP3 / ASC | B11: P2X7 / NLRP3 | C11: 2 | D11: Pathway inhibitors
A12: JAK/STAT3 | B12: IL-6 / JAK-STAT3 | C12: 2 | D12: Pathway inhibitors
A13: Glial inhibition | B13: Broad anti-inflammatory | C13: 3 | D13: Broad agents
... A20: Antibiotic | B20: Broad anti-inflammatory | C20: 3 | D20: Broad agents

Sheet References
A1: Ref. | B1: Citation | C1: Authors | D1: Title | E1: Journal | F1: Year | G1: DOI | H1: Experiments in wheel | I1: Full reference (as in manuscript)
A2: 49 | B2: Cueva Vargas et al., 2015 | C2: Cueva Vargas JL, Osswald IK, Unsain N, Aurousseau MR, Barker PA, Bowie D, et al | D2: Soluble Tumor Necrosis Factor Alpha Promotes Retinal Ganglion Cell Death in Glaucoma via Calcium-Permeable AMPA Receptor Activation | E2: J Neurosci | F2: 2015 | G2: https://doi.org/10.1523/JNEUROSCI.1273-15.2015 | H2: =COUNTIFS(Experiments!$G$2:$G$83,A2,Experiments!$T$2:$T$83,"yes") -> 1 | I2: Cueva Vargas JL, Osswald IK, Unsain N, Aurousseau MR, Barker PA, Bowie D, et al. Soluble Tumor Necrosis Factor Alpha Promotes Retinal Ganglion Cell Death in Glaucoma via Calcium-Permeable AMPA Receptor Activation. J Neurosci. 2015;35:12088–102.
A3: 55 | B3: Roh et al., 2012 | C3: Roh M, Zhang Y, Murakami Y, Thanos A, Lee SC, Vavvas DG, et al | D3: Etanercept, a Widely Used Inhibitor of Tumor Necrosis Factor-α (TNF- α), Prevents Retinal Ganglion Cell Loss in a Rat Model of Glaucoma | E3: PLoS One | F3: 2012 | G3: https://doi.org/10.1371/journal.pone.0040065 | H3: =COUNTIFS(Experiments!$G$2:$G$83,A3,Experiments!$T$2:$T$83,"yes") -> 1 | I3: Roh M, Zhang Y, Murakami Y, Thanos A, Lee SC, Vavvas DG, et al. Etanercept, a Widely Used Inhibitor of Tumor Necrosis Factor-α (TNF- α), Prevents Retinal Ganglion Cell Loss in a Rat Model of Glaucoma. PLoS One. 2012;7:e40065.
A4: 56 | B4: Tse et al., 2018 | C4: Tse BC, Dvoriantchikova G, Tao W, Gallo RA, Lee JY, Pappas S, et al | D4: Tumor Necrosis Factor Inhibition in the Acute Management of Traumatic Optic Neuropathy | E4: Invest Ophthalmol Vis Sci | F4: 2018 | G4: https://doi.org/10.1167/iovs.18-24431 | H4: =COUNTIFS(Experiments!$G$2:$G$83,A4,Experiments!$T$2:$T$83,"yes") -> 1 | I4: Tse BC, Dvoriantchikova G, Tao W, Gallo RA, Lee JY, Pappas S, et al. Tumor Necrosis Factor Inhibition in the Acute Management of Traumatic Optic Neuropathy. Invest Ophthalmol Vis Sci. 2018;59:2905–12.
A5: 57 | B5: Bae et al., 2016 | C5: Bae HW, Lee N, Seong GJ, Rho S, Hong S, Kim CY | D5: Protective effect of etanercept, an inhibitor of tumor necrosis factor-α, in a rat model of retinal ischemia | E5: BMC Ophthalmology | F5: 2016 | G5: https://doi.org/10.1186/s12886-016-0262-9 | H5: =COUNTIFS(Experiments!$G$2:$G$83,A5,Experiments!$T$2:$T$83,"yes") -> 1 | I5: Bae HW, Lee N, Seong GJ, Rho S, Hong S, Kim CY. Protective effect of etanercept, an inhibitor of tumor necrosis factor-α, in a rat model of retinal ischemia. BMC Ophthalmology. 2016;16:75.
A6: 58 | B6: Cade et al., 2014 | C6: Cade F, Paschalis EI, Regatieri CV, Vavvas DG, Dana R, Dohlman CH | D6: Alkali Burn to the Eye: Protection Using TNF-α Inhibition | E6: Cornea | F6: 2014 | G6: https://doi.org/10.1097/ICO.0000000000000071 | H6: =COUNTIFS(Experiments!$G$2:$G$83,A6,Experiments!$T$2:$T$83,"yes") -> 1 | I6: Cade F, Paschalis EI, Regatieri CV, Vavvas DG, Dana R, Dohlman CH. Alkali Burn to the Eye: Protection Using TNF-α Inhibition. Cornea. 2014;33:382.
A7: 59 | B7: Paschalis et al., 2017 | C7: Paschalis EI, Zhou C, Lei F, Scott N, Kapoulea V, Robert M-C, et al | D7: Mechanisms of Retinal Damage after Ocular Alkali Burns | E7: The American Journal of Pathology | F7: 2017 | G7: https://doi.org/10.1016/j.ajpath.2017.02.005 | H7: =COUNTIFS(Experiments!$G$2:$G$83,A7,Experiments!$T$2:$T$83,"yes") -> 2 | I7: Paschalis EI, Zhou C, Lei F, Scott N, Kapoulea V, Robert M-C, et al. Mechanisms of Retinal Damage after Ocular Alkali Burns. The American Journal of Pathology. 2017;187:1327–42.
A8: 60 | B8: Paschalis et al., 2024 | C8: Paschalis EI, Zhou C, Sharma J, Dohlman TH, Kim S, Lei F, et al | D8: The prophylactic value of TNF-α inhibitors against retinal cell apoptosis and optic nerve axon loss after corneal surgery or trauma | E8: Acta Ophthalmologica | F8: 2024 | G8: https://doi.org/10.1111/aos.15786 | H8: =COUNTIFS(Experiments!$G$2:$G$83,A8,Experiments!$T$2:$T$83,"yes") -> 1 | I8: Paschalis EI, Zhou C, Sharma J, Dohlman TH, Kim S, Lei F, et al. The prophylactic value of TNF-α inhibitors against retinal cell apoptosis and optic nerve axon loss after corneal surgery or trauma. Acta Ophthalmologica. 2024;102:e381–94.
A9: 62 | B9: Lucas-Ruiz et al., 2019 | C9: Lucas-Ruiz F, Galindo-Romero C, Salinas-Navarro M, González-Riquelme MJ, Vidal-Sanz M, Agudo Barriuso M | D9: Systemic and Intravitreal Antagonism of the TNFR1 Signaling Pathway Delays Axotomy-Induced Retinal Ganglion Cell Loss | E9: Front Neurosci | F9: 2019 | G9: https://doi.org/10.3389/fnins.2019.01096 | H9: =COUNTIFS(Experiments!$G$2:$G$83,A9,Experiments!$T$2:$T$83,"yes") -> 3 | I9: Lucas-Ruiz F, Galindo-Romero C, Salinas-Navarro M, González-Riquelme MJ, Vidal-Sanz M, Agudo Barriuso M. Systemic and Intravitreal Antagonism of the TNFR1 Signaling Pathway Delays Axotomy-Induced Retinal Ganglion Cell Loss. Front Neurosci. 2019;13:1096.
A10: 71 | B10: Yoneda et al., 2001 | C10: Yoneda S, Tanihara H, Kido N, Honda Y, Goto W, Hara H, et al | D10: Interleukin-1beta mediates ischemic injury in the rat retina | E10: Exp Eye Res | F10: 2001 | G10: https://doi.org/10.1006/exer.2001.1072 | H10: =COUNTIFS(Experiments!$G$2:$G$83,A10,Experiments!$T$2:$T$83,"yes") -> 1 | I10: Yoneda S, Tanihara H, Kido N, Honda Y, Goto W, Hara H, et al. Interleukin-1beta mediates ischemic injury in the rat retina. Exp Eye Res. 2001;73:661–7.
A11: 72 | B11: Evans et al., 2020 | C11: Evans LP, Woll AW, Wu S, Todd BP, Hehr N, Hedberg-Buenz A, et al | D11: Modulation of Post-Traumatic Immune Response Using the IL-1 Receptor Antagonist Anakinra for Improved Visual Outcomes | E11: J Neurotrauma | F11: 2020 | G11: https://doi.org/10.1089/neu.2019.6725 | H11: =COUNTIFS(Experiments!$G$2:$G$83,A11,Experiments!$T$2:$T$83,"yes") -> 1 | I11: Evans LP, Woll AW, Wu S, Todd BP, Hehr N, Hedberg-Buenz A, et al. Modulation of Post-Traumatic Immune Response Using the IL-1 Receptor Antagonist Anakinra for Improved Visual Outcomes. J Neurotrauma. 2020;37:1463–80.
A12: 80 | B12: Robinson et al., 2020 | C12: Robinson R, Srinivasan M, Shanmugam A, Ward A, Ganapathy V, Bloom J, et al | D12: Interleukin-6 trans-signaling inhibition prevents oxidative stress in a mouse model of early diabetic retinopathy | E12: Redox Biol | F12: 2020 | G12: https://doi.org/10.1016/j.redox.2020.101574 | H12: =COUNTIFS(Experiments!$G$2:$G$83,A12,Experiments!$T$2:$T$83,"yes") -> 1 | I12: Robinson R, Srinivasan M, Shanmugam A, Ward A, Ganapathy V, Bloom J, et al. Interleukin-6 trans-signaling inhibition prevents oxidative stress in a mouse model of early diabetic retinopathy. Redox Biol. 2020;34:101574.
A13: 83 | B13: Sakamoto et al., 2017 | C13: Sakamoto K, Okuwaki T, Ushikubo H, Mori A, Nakahara T, Ishii K | D13: Activation inhibitors of nuclear factor kappa B protect neurons against the NMDA-induced damage in the rat retina | E13: Journal of Pharmacological Sciences | F13: 2017 | G13: https://doi.org/10.1016/j.jphs.2017.09.031 | H13: =COUNTIFS(Experiments!$G$2:$G$83,A13,Experiments!$T$2:$T$83,"yes") -> 2 | I13: Sakamoto K, Okuwaki T, Ushikubo H, Mori A, Nakahara T, Ishii K. Activation inhibitors of nuclear factor kappa B protect neurons against the NMDA-induced damage in the rat retina. Journal of Pharmacological Sciences. 2017;135:72–80.
... A30: 102 | B30: Do et al., 2017 | C30: Do Y-J, Sul J-W, Jang K-H, Kang NS, Kim Y-H, Kim Y-G, et al | D30: A novel RIPK1 inhibitor that prevents retinal degeneration in a rat glaucoma model | E30: Experimental Cell Research | F30: 2017 | G30: https://doi.org/10.1016/j.yexcr.2017.08.012 | H30: =COUNTIFS(Experiments!$G$2:$G$83,A30,Experiments!$T$2:$T$83,"yes") -> 1 | I30: Do Y-J, Sul J-W, Jang K-H, Kang NS, Kim Y-H, Kim Y-G, et al. A novel RIPK1 inhibitor that prevents retinal degeneration in a rat glaucoma model. Experimental Cell Research. 2017;359:30–8.
A31: 103 | B31: Liu et al., 2011 | C31: Liu H, Sun H, Liu C | D31: Interference of the apoptotic signaling pathway in RGC stress response by SP600125 in moderate ocular hypertensive rats | E31: Chin J Physiol | F31: 2011 | H31: =COUNTIFS(Experiments!$G$2:$G$83,A31,Experiments!$T$2:$T$83,"yes") -> 1 | I31: Liu H, Sun H, Liu C. Interference of the apoptotic signaling pathway in RGC stress response by SP600125 in moderate ocular hypertensive rats. Chin J Physiol. 2011;54:124–32.
A32: 104 | B32: Sun et al., 2011 | C32: Sun H, Wang Y, Pang I-H, Shen J, Tang X, Li Y, et al | D32: Protective effect of a JNK inhibitor against retinal ganglion cell loss induced by acute moderate ocular hypertension | E32: Mol Vis | F32: 2011 | H32: =COUNTIFS(Experiments!$G$2:$G$83,A32,Experiments!$T$2:$T$83,"yes") -> 1 | I32: Sun H, Wang Y, Pang I-H, Shen J, Tang X, Li Y, et al. Protective effect of a JNK inhibitor against retinal ganglion cell loss induced by acute moderate ocular hypertension. Mol Vis. 2011;17:864–75.
A33: 105 | B33: Kim et al., 2016 | C33: Kim B-J, Silverman SM, Liu Y, Wordinger RJ, Pang I-H, Clark AF | D33: In vitro and in vivo neuroprotective effects of cJun N-terminal kinase inhibitors on retinal ganglion cells | E33: Molecular Neurodegeneration | F33: 2016 | G33: https://doi.org/10.1186/s13024-016-0093-4 | H33: =COUNTIFS(Experiments!$G$2:$G$83,A33,Experiments!$T$2:$T$83,"yes") -> 1 | I33: Kim B-J, Silverman SM, Liu Y, Wordinger RJ, Pang I-H, Clark AF. In vitro and in vivo neuroprotective effects of cJun N-terminal kinase inhibitors on retinal ganglion cells. Molecular Neurodegeneration. 2016;11:30.
A34: 106 | B34: Wang et al., 2021 | C34: Wang Y, Chen S, Wang J, Liu Y, Chen Y, Wen T, et al | D34: MicroRNA-93/STAT3 signalling pathway mediates retinal microglial activation and protects retinal ganglion cells in an acute ocular hypertension model | E34: Cell Death Dis | F34: 2021 | G34: https://doi.org/10.1038/s41419-020-03337-5 | H34: =COUNTIFS(Experiments!$G$2:$G$83,A34,Experiments!$T$2:$T$83,"yes") -> 1 | I34: Wang Y, Chen S, Wang J, Liu Y, Chen Y, Wen T, et al. MicroRNA-93/STAT3 signalling pathway mediates retinal microglial activation and protects retinal ganglion cells in an acute ocular hypertension model. Cell Death Dis. 2021;12:41.
A35: 107 | B35: Husain et al., 2021 | C35: Husain S, Zaidi SAH, Singh S, Guzman W, Mehrotra S | D35: Reduction of Neuroinflammation by δ-Opioids Via STAT3-Dependent Pathway in Chronic Glaucoma Model | E35: Front Pharmacol | F35: 2021 | G35: https://doi.org/10.3389/fphar.2021.601404 | H35: =COUNTIFS(Experiments!$G$2:$G$83,A35,Experiments!$T$2:$T$83,"yes") -> 1 | I35: Husain S, Zaidi SAH, Singh S, Guzman W, Mehrotra S. Reduction of Neuroinflammation by δ-Opioids Via STAT3-Dependent Pathway in Chronic Glaucoma Model. Front Pharmacol. 2021;12:601404.
A36: 109 | B36: Guan et al., 2025 | C36: Guan C, Zhang L, Fomo KN, Yang J, Pfeiffer N, Grus FH | D36: Targeting glial fibrillary acidic protein in glaucoma: a monoclonal antibody approach to modulate glial reactivity and neuroinflammation for neuroprotection | E36: J Neuroinflammation | F36: 2025 | G36: https://doi.org/10.1186/s12974-025-03482-8 | H36: =COUNTIFS(Experiments!$G$2:$G$83,A36,Experiments!$T$2:$T$83,"yes") -> 1 | I36: Guan C, Zhang L, Fomo KN, Yang J, Pfeiffer N, Grus FH. Targeting glial fibrillary acidic protein in glaucoma: a monoclonal antibody approach to modulate glial reactivity and neuroinflammation for neuroprotection. J Neuroinflammation. 2025;22:159.
A37: 110 | B37: Baptiste et al., 2005 | C37: Baptiste DC, Powell KJ, Jollimore C a | D37: B, Hamilton C, LeVatte TL, Archibald ML, et al | E37: Effects of minocycline and tetracycline on retinal ganglion cell survival after axotomy | F37: 2005 | G37: https://doi.org/10.1016/j.neuroscience.2005.04.011 | H37: =COUNTIFS(Experiments!$G$2:$G$83,A37,Experiments!$T$2:$T$83,"yes") -> 1 | I37: Baptiste DC, Powell KJ, Jollimore C a. B, Hamilton C, LeVatte TL, Archibald ML, et al. Effects of minocycline and tetracycline on retinal ganglion cell survival after axotomy. Neuroscience. 2005;134:575–82.
A38: 111 | B38: Shimazawa et al., 2005 | C38: Shimazawa M, Yamashima T, Agarwal N, Hara H | D38: Neuroprotective effects of minocycline against in vitro and in vivo retinal ganglion cell damage | E38: Brain Research | F38: 2005 | G38: https://doi.org/10.1016/j.brainres.2005.06.053 | H38: =COUNTIFS(Experiments!$G$2:$G$83,A38,Experiments!$T$2:$T$83,"yes") -> 1 | I38: Shimazawa M, Yamashima T, Agarwal N, Hara H. Neuroprotective effects of minocycline against in vitro and in vivo retinal ganglion cell damage. Brain Research. 2005;1053:185–94.
